2022-12-26 14:42:02.457 [INFO] ALL 'A' USER COLLECTING (user_sampler.py:51)
2022-12-26 14:44:10.451 [INFO] 'B12' USER SAMPLING (user_sampler.py:87)
2022-12-26 14:48:44.428 [WARNING] 502 Server Error: Bad Gateway for url: https://lol.api.ggq.gg/application/v1/summoners/u1zGEHASde6AVqESVdhlZCVEZ7sVxcJHbIckhc7uXvmhJZ3dsZ09ZG_P0-1M__psKKhFvs7GjtYdDA (api_client.py:57)
Traceback (most recent call last):
  File "c:\Users\User\PythonProject\ai-python-coach-gathering-server-1\api_client\api_client.py", line 46, in _http_request
    r.raise_for_status()
  File "C:\Users\User\AppData\Local\Packages\PythonSoftwareFoundation.Python.3.10_qbz5n2kfra8p0\LocalCache\local-packages\Python310\site-packages\requests\models.py", line 940, in raise_for_status
    raise HTTPError(http_error_msg, response=self)
requests.exceptions.HTTPError: 502 Server Error: Bad Gateway for url: https://lol.api.ggq.gg/application/v1/summoners/u1zGEHASde6AVqESVdhlZCVEZ7sVxcJHbIckhc7uXvmhJZ3dsZ09ZG_P0-1M__psKKhFvs7GjtYdDA
2022-12-26 15:07:02.907 [WARNING] 502 Server Error: Bad Gateway for url: https://lol.api.ggq.gg/application/v1/summoners/4PPbLT0sjfx-eq3I0pjr_gJlRBNsdHg-JsBR5Ljq8nwD_P3VLEcZzBFQM2ld079pFnFb-E3GjGg3eg/match-ids?queue=420&start=0&count=50&startTime=1670425200.0&endTime=1671894000.0 (api_client.py:57)
Traceback (most recent call last):
  File "c:\Users\User\PythonProject\ai-python-coach-gathering-server-1\api_client\api_client.py", line 46, in _http_request
    r.raise_for_status()
  File "C:\Users\User\AppData\Local\Packages\PythonSoftwareFoundation.Python.3.10_qbz5n2kfra8p0\LocalCache\local-packages\Python310\site-packages\requests\models.py", line 940, in raise_for_status
    raise HTTPError(http_error_msg, response=self)
requests.exceptions.HTTPError: 502 Server Error: Bad Gateway for url: https://lol.api.ggq.gg/application/v1/summoners/4PPbLT0sjfx-eq3I0pjr_gJlRBNsdHg-JsBR5Ljq8nwD_P3VLEcZzBFQM2ld079pFnFb-E3GjGg3eg/match-ids?queue=420&start=0&count=50&startTime=1670425200.0&endTime=1671894000.0
2022-12-26 15:12:15.589 [WARNING] 502 Server Error: Bad Gateway for url: https://lol.api.ggq.gg/application/v1/summoners/IbvNP7Q6wTsNOV4si18pLizgk77DU3C7zSYmunWngRkmlVjDOiSH3j_aP7HHG_lHHbed8gqdv3bZ0g (api_client.py:57)
Traceback (most recent call last):
  File "c:\Users\User\PythonProject\ai-python-coach-gathering-server-1\api_client\api_client.py", line 46, in _http_request
    r.raise_for_status()
  File "C:\Users\User\AppData\Local\Packages\PythonSoftwareFoundation.Python.3.10_qbz5n2kfra8p0\LocalCache\local-packages\Python310\site-packages\requests\models.py", line 940, in raise_for_status
    raise HTTPError(http_error_msg, response=self)
requests.exceptions.HTTPError: 502 Server Error: Bad Gateway for url: https://lol.api.ggq.gg/application/v1/summoners/IbvNP7Q6wTsNOV4si18pLizgk77DU3C7zSYmunWngRkmlVjDOiSH3j_aP7HHG_lHHbed8gqdv3bZ0g
2022-12-26 15:25:19.158 [WARNING] 503 Server Error: Service Unavailable for url: https://lol.api.ggq.gg/gateway/v2/lol/match/v5/matches/KR_6257686222 (api_client.py:57)
Traceback (most recent call last):
  File "c:\Users\User\PythonProject\ai-python-coach-gathering-server-1\api_client\api_client.py", line 46, in _http_request
    r.raise_for_status()
  File "C:\Users\User\AppData\Local\Packages\PythonSoftwareFoundation.Python.3.10_qbz5n2kfra8p0\LocalCache\local-packages\Python310\site-packages\requests\models.py", line 940, in raise_for_status
    raise HTTPError(http_error_msg, response=self)
requests.exceptions.HTTPError: 503 Server Error: Service Unavailable for url: https://lol.api.ggq.gg/gateway/v2/lol/match/v5/matches/KR_6257686222
2022-12-26 15:32:53.403 [WARNING] 502 Server Error: Bad Gateway for url: https://lol.api.ggq.gg/gateway/v2/lol/match/v5/matches/KR_6253840907 (api_client.py:57)
Traceback (most recent call last):
  File "c:\Users\User\PythonProject\ai-python-coach-gathering-server-1\api_client\api_client.py", line 46, in _http_request
    r.raise_for_status()
  File "C:\Users\User\AppData\Local\Packages\PythonSoftwareFoundation.Python.3.10_qbz5n2kfra8p0\LocalCache\local-packages\Python310\site-packages\requests\models.py", line 940, in raise_for_status
    raise HTTPError(http_error_msg, response=self)
requests.exceptions.HTTPError: 502 Server Error: Bad Gateway for url: https://lol.api.ggq.gg/gateway/v2/lol/match/v5/matches/KR_6253840907
2022-12-26 16:08:12.938 [WARNING] 502 Server Error: Bad Gateway for url: https://lol.api.ggq.gg/application/v1/summoners/ftJEIkJ_rRnonlw5bLZPViFTk8q9PbXvzc0BUFnAxNlxfvH2O9WQ0eSuRVSh8qo-RJERXh6Y9o9v5w (api_client.py:57)
Traceback (most recent call last):
  File "c:\Users\User\PythonProject\ai-python-coach-gathering-server-1\api_client\api_client.py", line 46, in _http_request
    r.raise_for_status()
  File "C:\Users\User\AppData\Local\Packages\PythonSoftwareFoundation.Python.3.10_qbz5n2kfra8p0\LocalCache\local-packages\Python310\site-packages\requests\models.py", line 940, in raise_for_status
    raise HTTPError(http_error_msg, response=self)
requests.exceptions.HTTPError: 502 Server Error: Bad Gateway for url: https://lol.api.ggq.gg/application/v1/summoners/ftJEIkJ_rRnonlw5bLZPViFTk8q9PbXvzc0BUFnAxNlxfvH2O9WQ0eSuRVSh8qo-RJERXh6Y9o9v5w
2022-12-26 16:35:59.348 [WARNING] 502 Server Error: Bad Gateway for url: https://lol.api.ggq.gg/application/v1/summoners/ehIaOP862H-RQIUDIZohg-As4UpZf8IC4DOr5yodQfgwIPB4t0hwZUtVYbhNE2kVfAsHHomwe1YJfw (api_client.py:57)
Traceback (most recent call last):
  File "c:\Users\User\PythonProject\ai-python-coach-gathering-server-1\api_client\api_client.py", line 46, in _http_request
    r.raise_for_status()
  File "C:\Users\User\AppData\Local\Packages\PythonSoftwareFoundation.Python.3.10_qbz5n2kfra8p0\LocalCache\local-packages\Python310\site-packages\requests\models.py", line 940, in raise_for_status
    raise HTTPError(http_error_msg, response=self)
requests.exceptions.HTTPError: 502 Server Error: Bad Gateway for url: https://lol.api.ggq.gg/application/v1/summoners/ehIaOP862H-RQIUDIZohg-As4UpZf8IC4DOr5yodQfgwIPB4t0hwZUtVYbhNE2kVfAsHHomwe1YJfw
2022-12-26 16:50:44.849 [WARNING] 502 Server Error: Bad Gateway for url: https://lol.api.ggq.gg/application/v1/summoners/D5vyKljY0mPTLPuJuvbjlP0hPB0YJ6UxJdPEMCQguWpvrd786QlmA_S0t-aJFsTLQuqOG8KYwsC23A (api_client.py:57)
Traceback (most recent call last):
  File "c:\Users\User\PythonProject\ai-python-coach-gathering-server-1\api_client\api_client.py", line 46, in _http_request
    r.raise_for_status()
  File "C:\Users\User\AppData\Local\Packages\PythonSoftwareFoundation.Python.3.10_qbz5n2kfra8p0\LocalCache\local-packages\Python310\site-packages\requests\models.py", line 940, in raise_for_status
    raise HTTPError(http_error_msg, response=self)
requests.exceptions.HTTPError: 502 Server Error: Bad Gateway for url: https://lol.api.ggq.gg/application/v1/summoners/D5vyKljY0mPTLPuJuvbjlP0hPB0YJ6UxJdPEMCQguWpvrd786QlmA_S0t-aJFsTLQuqOG8KYwsC23A
2022-12-26 17:06:08.981 [WARNING] 500 Server Error: Internal Server Error for url: https://lol.api.ggq.gg/application/v1/summoners/vlAvzYAI8jgQ95PvlRvURf34CsvxwWPpE_5Ns8eaSuUj_bc_YwyZM5h29qvxUr5s-L3UP9Rhi_vENA (api_client.py:57)
Traceback (most recent call last):
  File "c:\Users\User\PythonProject\ai-python-coach-gathering-server-1\api_client\api_client.py", line 46, in _http_request
    r.raise_for_status()
  File "C:\Users\User\AppData\Local\Packages\PythonSoftwareFoundation.Python.3.10_qbz5n2kfra8p0\LocalCache\local-packages\Python310\site-packages\requests\models.py", line 940, in raise_for_status
    raise HTTPError(http_error_msg, response=self)
requests.exceptions.HTTPError: 500 Server Error: Internal Server Error for url: https://lol.api.ggq.gg/application/v1/summoners/vlAvzYAI8jgQ95PvlRvURf34CsvxwWPpE_5Ns8eaSuUj_bc_YwyZM5h29qvxUr5s-L3UP9Rhi_vENA
2022-12-26 17:06:09.270 [WARNING] 500 Server Error: Internal Server Error for url: https://lol.api.ggq.gg/application/v1/summoners/BKqbRkPRduWmzlikgpcn_dD1_vLpsaJ0y3y-yqeChrOQjshi3AbDpYbKRXweRTwBKHIRzc5se0JjlQ (api_client.py:57)
Traceback (most recent call last):
  File "c:\Users\User\PythonProject\ai-python-coach-gathering-server-1\api_client\api_client.py", line 46, in _http_request
    r.raise_for_status()
  File "C:\Users\User\AppData\Local\Packages\PythonSoftwareFoundation.Python.3.10_qbz5n2kfra8p0\LocalCache\local-packages\Python310\site-packages\requests\models.py", line 940, in raise_for_status
    raise HTTPError(http_error_msg, response=self)
requests.exceptions.HTTPError: 500 Server Error: Internal Server Error for url: https://lol.api.ggq.gg/application/v1/summoners/BKqbRkPRduWmzlikgpcn_dD1_vLpsaJ0y3y-yqeChrOQjshi3AbDpYbKRXweRTwBKHIRzc5se0JjlQ
2022-12-26 17:28:36.185 [WARNING] 502 Server Error: Bad Gateway for url: https://lol.api.ggq.gg/application/v1/summoners/rMFs60-n05eAwNfzQEq9BVoXXnP-M0hajEdfpoDomzkuy7T_FjzuTMuPm4AsfoTCNiy50f2DTXgE_g (api_client.py:57)
Traceback (most recent call last):
  File "c:\Users\User\PythonProject\ai-python-coach-gathering-server-1\api_client\api_client.py", line 46, in _http_request
    r.raise_for_status()
  File "C:\Users\User\AppData\Local\Packages\PythonSoftwareFoundation.Python.3.10_qbz5n2kfra8p0\LocalCache\local-packages\Python310\site-packages\requests\models.py", line 940, in raise_for_status
    raise HTTPError(http_error_msg, response=self)
requests.exceptions.HTTPError: 502 Server Error: Bad Gateway for url: https://lol.api.ggq.gg/application/v1/summoners/rMFs60-n05eAwNfzQEq9BVoXXnP-M0hajEdfpoDomzkuy7T_FjzuTMuPm4AsfoTCNiy50f2DTXgE_g
2022-12-26 17:36:16.977 [WARNING] 502 Server Error: Bad Gateway for url: https://lol.api.ggq.gg/application/v1/summoners/5LTZjvhdVUVaQNoYWSrq0otBMxALvgN4yReUqkmu15G_QKOfWNMOfmWBkXcb4JngvUyU2UOdi0iKAg (api_client.py:57)
Traceback (most recent call last):
  File "c:\Users\User\PythonProject\ai-python-coach-gathering-server-1\api_client\api_client.py", line 46, in _http_request
    r.raise_for_status()
  File "C:\Users\User\AppData\Local\Packages\PythonSoftwareFoundation.Python.3.10_qbz5n2kfra8p0\LocalCache\local-packages\Python310\site-packages\requests\models.py", line 940, in raise_for_status
    raise HTTPError(http_error_msg, response=self)
requests.exceptions.HTTPError: 502 Server Error: Bad Gateway for url: https://lol.api.ggq.gg/application/v1/summoners/5LTZjvhdVUVaQNoYWSrq0otBMxALvgN4yReUqkmu15G_QKOfWNMOfmWBkXcb4JngvUyU2UOdi0iKAg
2022-12-26 18:08:04.901 [INFO] Tier: TierGroup.B12 complete collecting (collecting_batch.py:41)
2022-12-26 18:08:04.903 [INFO] User input is initialized from C:\Users\User\PythonProject\ai-python-coach-gathering-server-1\save_files\12.23\A_user_list.txt (user_sampler.py:67)
2022-12-26 18:08:04.903 [INFO] Tier: TierGroup.A complete collecting (collecting_batch.py:45)
2022-12-26 18:08:04.904 [INFO] Tier: TierGroup.B12 - Starting to post request to download server (collecting_batch.py:52)
2022-12-26 18:08:12.723 [INFO] Tier: TierGroup.B12 - Complete to post request to download server (collecting_batch.py:64)
2022-12-26 18:08:12.724 [INFO] current download queue: 416 (collecting_batch.py:68)
2022-12-26 18:08:12.724 [INFO] Tier: TierGroup.A - Starting to post request to download server (collecting_batch.py:52)
2022-12-27 15:43:26.378 [INFO] User input is initialized from C:\Users\User\PythonProject\ai-python-coach-gathering-server-1\save_files\12.23\A_user_list.txt (user_sampler.py:67)
2022-12-27 15:44:53.606 [INFO] User input is initialized from C:\Users\User\PythonProject\ai-python-coach-gathering-server-1\save_files\12.23\A_user_list.txt (user_sampler.py:67)
2022-12-27 15:48:18.668 [INFO] ALL 'A' USER COLLECTING (user_sampler.py:51)
2022-12-27 17:00:05.494 [WARNING] 503 Server Error: Service Unavailable for url: https://lol.api.ggq.gg/gateway/v2/lol/match/v5/matches/KR_6252567251 (api_client.py:57)
Traceback (most recent call last):
  File "c:\Users\User\PythonProject\ai-python-coach-gathering-server-1\api_client\api_client.py", line 46, in _http_request
    r.raise_for_status()
  File "C:\Users\User\AppData\Local\Packages\PythonSoftwareFoundation.Python.3.10_qbz5n2kfra8p0\LocalCache\local-packages\Python310\site-packages\requests\models.py", line 940, in raise_for_status
    raise HTTPError(http_error_msg, response=self)
requests.exceptions.HTTPError: 503 Server Error: Service Unavailable for url: https://lol.api.ggq.gg/gateway/v2/lol/match/v5/matches/KR_6252567251
2022-12-27 17:14:34.346 [WARNING] 502 Server Error: Bad Gateway for url: https://lol.api.ggq.gg/gateway/v2/lol/match/v5/matches/KR_6252152356 (api_client.py:57)
Traceback (most recent call last):
  File "c:\Users\User\PythonProject\ai-python-coach-gathering-server-1\api_client\api_client.py", line 46, in _http_request
    r.raise_for_status()
  File "C:\Users\User\AppData\Local\Packages\PythonSoftwareFoundation.Python.3.10_qbz5n2kfra8p0\LocalCache\local-packages\Python310\site-packages\requests\models.py", line 940, in raise_for_status
    raise HTTPError(http_error_msg, response=self)
requests.exceptions.HTTPError: 502 Server Error: Bad Gateway for url: https://lol.api.ggq.gg/gateway/v2/lol/match/v5/matches/KR_6252152356
2022-12-27 17:37:37.426 [INFO] Tier: TierGroup.A complete collecting (collecting_batch.py:47)
2022-12-27 17:37:37.427 [INFO] Tier: TierGroup.A - Starting to post request to download server (collecting_batch.py:54)
2022-12-27 17:39:17.313 [INFO] Tier: TierGroup.A - Complete to post request to download server (collecting_batch.py:66)
2022-12-27 17:39:17.313 [INFO] current download queue: 4733 (collecting_batch.py:70)
2022-12-28 09:36:10.671 [INFO] ALL 'A' USER COLLECTING (user_sampler.py:51)
2022-12-28 09:50:43.361 [WARNING] 502 Server Error: Bad Gateway for url: https://lol.api.ggq.gg/gateway/v2/lol/match/v5/matches/KR_6274875927 (api_client.py:57)
Traceback (most recent call last):
  File "c:\Users\User\PythonProject\ai-python-coach-gathering-server-1\api_client\api_client.py", line 46, in _http_request
    r.raise_for_status()
  File "C:\Users\User\AppData\Local\Packages\PythonSoftwareFoundation.Python.3.10_qbz5n2kfra8p0\LocalCache\local-packages\Python310\site-packages\requests\models.py", line 940, in raise_for_status
    raise HTTPError(http_error_msg, response=self)
requests.exceptions.HTTPError: 502 Server Error: Bad Gateway for url: https://lol.api.ggq.gg/gateway/v2/lol/match/v5/matches/KR_6274875927
2022-12-28 09:53:23.684 [WARNING] 502 Server Error: Bad Gateway for url: https://lol.api.ggq.gg/gateway/v2/lol/match/v5/matches/KR_6277547448 (api_client.py:57)
Traceback (most recent call last):
  File "c:\Users\User\PythonProject\ai-python-coach-gathering-server-1\api_client\api_client.py", line 46, in _http_request
    r.raise_for_status()
  File "C:\Users\User\AppData\Local\Packages\PythonSoftwareFoundation.Python.3.10_qbz5n2kfra8p0\LocalCache\local-packages\Python310\site-packages\requests\models.py", line 940, in raise_for_status
    raise HTTPError(http_error_msg, response=self)
requests.exceptions.HTTPError: 502 Server Error: Bad Gateway for url: https://lol.api.ggq.gg/gateway/v2/lol/match/v5/matches/KR_6277547448
2022-12-28 10:00:05.702 [WARNING] 502 Server Error: Bad Gateway for url: https://lol.api.ggq.gg/application/v1/summoners/j6w5tIzdUieGYbAsUmJSfQAGZqt3OCQFkaxbeEtbdNbYPqd2OS26dm-BTUi8kit1PbvVd6xxXdqhiw/match-ids?queue=420&start=0&count=100&startTime=1671721200.0&endTime=1672153200.0 (api_client.py:57)
Traceback (most recent call last):
  File "c:\Users\User\PythonProject\ai-python-coach-gathering-server-1\api_client\api_client.py", line 46, in _http_request
    r.raise_for_status()
  File "C:\Users\User\AppData\Local\Packages\PythonSoftwareFoundation.Python.3.10_qbz5n2kfra8p0\LocalCache\local-packages\Python310\site-packages\requests\models.py", line 940, in raise_for_status
    raise HTTPError(http_error_msg, response=self)
requests.exceptions.HTTPError: 502 Server Error: Bad Gateway for url: https://lol.api.ggq.gg/application/v1/summoners/j6w5tIzdUieGYbAsUmJSfQAGZqt3OCQFkaxbeEtbdNbYPqd2OS26dm-BTUi8kit1PbvVd6xxXdqhiw/match-ids?queue=420&start=0&count=100&startTime=1671721200.0&endTime=1672153200.0
2022-12-28 10:03:40.889 [INFO] Tier: TierGroup.A complete collecting (collecting_batch.py:47)
2022-12-28 10:03:40.890 [INFO] Tier: TierGroup.A - Starting to post request to download server (collecting_batch.py:54)
2022-12-28 10:05:46.725 [INFO] Tier: TierGroup.A - Complete to post request to download server (collecting_batch.py:66)
2022-12-28 10:05:46.726 [INFO] current download queue: 835 (collecting_batch.py:70)
2022-12-28 17:33:26.935 [INFO] User input is initialized from C:\Users\User\PythonProject\ai-python-coach-gathering-server-1\save_files\12.23\B12_user_list.txt (user_sampler.py:79)
2022-12-28 17:36:19.063 [INFO] User input is initialized from C:\Users\User\PythonProject\ai-python-coach-gathering-server-1\save_files\12.23\B12_user_list.txt (user_sampler.py:79)
2022-12-28 17:36:31.946 [INFO] User input is initialized from C:\Users\User\PythonProject\ai-python-coach-gathering-server-1\save_files\12.23\B12_user_list.txt (user_sampler.py:79)
2022-12-28 17:46:08.016 [INFO] User input is initialized from C:\Users\User\PythonProject\ai-python-coach-gathering-server-1\save_files\12.23\B12_user_list.txt (user_sampler.py:79)
2022-12-28 17:47:16.323 [INFO] 'B12' USER SAMPLING (user_sampler.py:87)
2022-12-28 18:07:13.155 [INFO] User input is initialized from C:\Users\User\PythonProject\ai-python-coach-gathering-server-1\save_files\12.23\B12_user_list.txt (user_sampler.py:79)
2022-12-28 18:29:41.966 [WARNING] 502 Server Error: Bad Gateway for url: https://lol.api.ggq.gg/gateway/v2/lol/match/v5/matches/KR_6278823882 (api_client.py:57)
Traceback (most recent call last):
  File "C:\Users\User\PythonProject\ai-python-coach-gathering-server-1\api_client\api_client.py", line 46, in _http_request
    r.raise_for_status()
  File "C:\Users\User\AppData\Local\Packages\PythonSoftwareFoundation.Python.3.10_qbz5n2kfra8p0\LocalCache\local-packages\Python310\site-packages\requests\models.py", line 940, in raise_for_status
    raise HTTPError(http_error_msg, response=self)
requests.exceptions.HTTPError: 502 Server Error: Bad Gateway for url: https://lol.api.ggq.gg/gateway/v2/lol/match/v5/matches/KR_6278823882
2022-12-28 18:35:59.726 [WARNING] 502 Server Error: Bad Gateway for url: https://lol.api.ggq.gg/application/v1/summoners/7tt0DoPUEwx4uV4J1DrHwEvwkfMXFM3jUEANlPysDJo2albpG2UBYH30k_c8RucWqalwG7eO281PTg (api_client.py:57)
Traceback (most recent call last):
  File "C:\Users\User\PythonProject\ai-python-coach-gathering-server-1\api_client\api_client.py", line 46, in _http_request
    r.raise_for_status()
  File "C:\Users\User\AppData\Local\Packages\PythonSoftwareFoundation.Python.3.10_qbz5n2kfra8p0\LocalCache\local-packages\Python310\site-packages\requests\models.py", line 940, in raise_for_status
    raise HTTPError(http_error_msg, response=self)
requests.exceptions.HTTPError: 502 Server Error: Bad Gateway for url: https://lol.api.ggq.gg/application/v1/summoners/7tt0DoPUEwx4uV4J1DrHwEvwkfMXFM3jUEANlPysDJo2albpG2UBYH30k_c8RucWqalwG7eO281PTg
2022-12-28 18:39:28.475 [INFO] Tier: TierGroup.B12 complete collecting (collecting_script.py:46)
2022-12-28 18:39:28.534 [INFO] User input is initialized from C:\Users\User\PythonProject\ai-python-coach-gathering-server-1\save_files\12.23\B34_user_list.txt (user_sampler.py:79)
2022-12-28 18:42:05.714 [WARNING] 500 Server Error: Internal Server Error for url: https://lol.api.ggq.gg/application/v1/summoners/J1QDKjlT_tgpEZRCOQQMop6ZkqS4iobIZsoQ49izT8VxBe6wD-ilrPSrLZZWljvbtByfnuMYU9ZPLg (api_client.py:57)
Traceback (most recent call last):
  File "C:\Users\User\PythonProject\ai-python-coach-gathering-server-1\api_client\api_client.py", line 46, in _http_request
    r.raise_for_status()
  File "C:\Users\User\AppData\Local\Packages\PythonSoftwareFoundation.Python.3.10_qbz5n2kfra8p0\LocalCache\local-packages\Python310\site-packages\requests\models.py", line 940, in raise_for_status
    raise HTTPError(http_error_msg, response=self)
requests.exceptions.HTTPError: 500 Server Error: Internal Server Error for url: https://lol.api.ggq.gg/application/v1/summoners/J1QDKjlT_tgpEZRCOQQMop6ZkqS4iobIZsoQ49izT8VxBe6wD-ilrPSrLZZWljvbtByfnuMYU9ZPLg
2022-12-28 18:42:19.544 [WARNING] 500 Server Error: Internal Server Error for url: https://lol.api.ggq.gg/application/v1/summoners/N0M8dvqmVMwXnzzotVelZ-qnjxntAghWHi784Rx_yELZK6WFU1b_0ojxszCKPUDit2-flUV1zqZVpg (api_client.py:57)
Traceback (most recent call last):
  File "C:\Users\User\PythonProject\ai-python-coach-gathering-server-1\api_client\api_client.py", line 46, in _http_request
    r.raise_for_status()
  File "C:\Users\User\AppData\Local\Packages\PythonSoftwareFoundation.Python.3.10_qbz5n2kfra8p0\LocalCache\local-packages\Python310\site-packages\requests\models.py", line 940, in raise_for_status
    raise HTTPError(http_error_msg, response=self)
requests.exceptions.HTTPError: 500 Server Error: Internal Server Error for url: https://lol.api.ggq.gg/application/v1/summoners/N0M8dvqmVMwXnzzotVelZ-qnjxntAghWHi784Rx_yELZK6WFU1b_0ojxszCKPUDit2-flUV1zqZVpg
2022-12-28 19:07:15.258 [WARNING] 502 Server Error: Bad Gateway for url: https://lol.api.ggq.gg/application/v1/summoners/LP84jfKa9iUGrOkAJKOgckd1UedYmXq_4fDN4x__8fDdSMCPMUBiDWH30oEN_K5zM5Zwvd_vl5IZNg (api_client.py:57)
Traceback (most recent call last):
  File "C:\Users\User\PythonProject\ai-python-coach-gathering-server-1\api_client\api_client.py", line 46, in _http_request
    r.raise_for_status()
  File "C:\Users\User\AppData\Local\Packages\PythonSoftwareFoundation.Python.3.10_qbz5n2kfra8p0\LocalCache\local-packages\Python310\site-packages\requests\models.py", line 940, in raise_for_status
    raise HTTPError(http_error_msg, response=self)
requests.exceptions.HTTPError: 502 Server Error: Bad Gateway for url: https://lol.api.ggq.gg/application/v1/summoners/LP84jfKa9iUGrOkAJKOgckd1UedYmXq_4fDN4x__8fDdSMCPMUBiDWH30oEN_K5zM5Zwvd_vl5IZNg
2022-12-28 19:09:32.491 [INFO] Tier: TierGroup.B34 complete collecting (collecting_script.py:46)
2022-12-28 19:09:32.552 [INFO] User input is initialized from C:\Users\User\PythonProject\ai-python-coach-gathering-server-1\save_files\12.23\S12_user_list.txt (user_sampler.py:79)
2022-12-28 19:29:57.534 [WARNING] 502 Server Error: Bad Gateway for url: https://lol.api.ggq.gg/application/v1/summoners/vSpDSyg_0G9isJOTNyBQO4vKZ6VwmM7pOLZne0zQ0iP1KZ6s1uTT62TAyHuFtug5zD_Wi-SHGw8DRw (api_client.py:57)
Traceback (most recent call last):
  File "C:\Users\User\PythonProject\ai-python-coach-gathering-server-1\api_client\api_client.py", line 46, in _http_request
    r.raise_for_status()
  File "C:\Users\User\AppData\Local\Packages\PythonSoftwareFoundation.Python.3.10_qbz5n2kfra8p0\LocalCache\local-packages\Python310\site-packages\requests\models.py", line 940, in raise_for_status
    raise HTTPError(http_error_msg, response=self)
requests.exceptions.HTTPError: 502 Server Error: Bad Gateway for url: https://lol.api.ggq.gg/application/v1/summoners/vSpDSyg_0G9isJOTNyBQO4vKZ6VwmM7pOLZne0zQ0iP1KZ6s1uTT62TAyHuFtug5zD_Wi-SHGw8DRw
2022-12-28 19:30:39.985 [INFO] Tier: TierGroup.S12 complete collecting (collecting_script.py:46)
2022-12-28 19:30:40.046 [INFO] User input is initialized from C:\Users\User\PythonProject\ai-python-coach-gathering-server-1\save_files\12.23\S34_user_list.txt (user_sampler.py:79)
2022-12-28 19:42:10.785 [INFO] Tier: TierGroup.S34 complete collecting (collecting_script.py:46)
2022-12-28 19:42:10.846 [INFO] User input is initialized from C:\Users\User\PythonProject\ai-python-coach-gathering-server-1\save_files\12.23\G12_user_list.txt (user_sampler.py:79)
2022-12-28 19:44:05.067 [WARNING] 500 Server Error: Internal Server Error for url: https://lol.api.ggq.gg/application/v1/summoners/Plpzx8nYyiluPHLj4K3FVvymBy0gA5FBkqGqYNAgD5xgGDGrLP99XBfR0JcpxGV1dPm4jghit1S7lw (api_client.py:57)
Traceback (most recent call last):
  File "C:\Users\User\PythonProject\ai-python-coach-gathering-server-1\api_client\api_client.py", line 46, in _http_request
    r.raise_for_status()
  File "C:\Users\User\AppData\Local\Packages\PythonSoftwareFoundation.Python.3.10_qbz5n2kfra8p0\LocalCache\local-packages\Python310\site-packages\requests\models.py", line 940, in raise_for_status
    raise HTTPError(http_error_msg, response=self)
requests.exceptions.HTTPError: 500 Server Error: Internal Server Error for url: https://lol.api.ggq.gg/application/v1/summoners/Plpzx8nYyiluPHLj4K3FVvymBy0gA5FBkqGqYNAgD5xgGDGrLP99XBfR0JcpxGV1dPm4jghit1S7lw
2022-12-28 19:44:05.820 [WARNING] 500 Server Error: Internal Server Error for url: https://lol.api.ggq.gg/application/v1/summoners/vAtJnn2gap2MO9rtbmqzHBo-sMIqpa1pZ3o3zHF-9G2Bz8qjM0rKgAoQb8lp34_xy_2W2Jm-1U2mRQ (api_client.py:57)
Traceback (most recent call last):
  File "C:\Users\User\PythonProject\ai-python-coach-gathering-server-1\api_client\api_client.py", line 46, in _http_request
    r.raise_for_status()
  File "C:\Users\User\AppData\Local\Packages\PythonSoftwareFoundation.Python.3.10_qbz5n2kfra8p0\LocalCache\local-packages\Python310\site-packages\requests\models.py", line 940, in raise_for_status
    raise HTTPError(http_error_msg, response=self)
requests.exceptions.HTTPError: 500 Server Error: Internal Server Error for url: https://lol.api.ggq.gg/application/v1/summoners/vAtJnn2gap2MO9rtbmqzHBo-sMIqpa1pZ3o3zHF-9G2Bz8qjM0rKgAoQb8lp34_xy_2W2Jm-1U2mRQ
2022-12-28 20:01:14.036 [INFO] Tier: TierGroup.G12 complete collecting (collecting_script.py:46)
2022-12-28 20:01:14.098 [INFO] User input is initialized from C:\Users\User\PythonProject\ai-python-coach-gathering-server-1\save_files\12.23\G34_user_list.txt (user_sampler.py:79)
2022-12-28 20:03:26.529 [WARNING] 502 Server Error: Bad Gateway for url: https://lol.api.ggq.gg/application/v1/summoners/CePPlEuBfy8vegOq970MUeZOgTxZokvY_0n0ByGqE4EkFD1Qol-pjHycGkDfr4LpN-9ONomtypcf7w (api_client.py:57)
Traceback (most recent call last):
  File "C:\Users\User\PythonProject\ai-python-coach-gathering-server-1\api_client\api_client.py", line 46, in _http_request
    r.raise_for_status()
  File "C:\Users\User\AppData\Local\Packages\PythonSoftwareFoundation.Python.3.10_qbz5n2kfra8p0\LocalCache\local-packages\Python310\site-packages\requests\models.py", line 940, in raise_for_status
    raise HTTPError(http_error_msg, response=self)
requests.exceptions.HTTPError: 502 Server Error: Bad Gateway for url: https://lol.api.ggq.gg/application/v1/summoners/CePPlEuBfy8vegOq970MUeZOgTxZokvY_0n0ByGqE4EkFD1Qol-pjHycGkDfr4LpN-9ONomtypcf7w
2022-12-28 20:13:55.892 [INFO] Tier: TierGroup.G34 complete collecting (collecting_script.py:46)
2022-12-28 20:13:55.955 [INFO] User input is initialized from C:\Users\User\PythonProject\ai-python-coach-gathering-server-1\save_files\12.23\P12_user_list.txt (user_sampler.py:79)
2022-12-28 20:39:46.368 [INFO] Tier: TierGroup.P12 complete collecting (collecting_script.py:46)
2022-12-28 20:39:46.432 [INFO] User input is initialized from C:\Users\User\PythonProject\ai-python-coach-gathering-server-1\save_files\12.23\P34_user_list.txt (user_sampler.py:79)
2022-12-28 20:40:06.611 [WARNING] 502 Server Error: Bad Gateway for url: https://lol.api.ggq.gg/application/v1/summoners/09h2gakf0VfGufDxZ53DgVdgyGxNhIcwvzSKZ4VRnREKcTlFlsXMQ0Li85X3BlBuzHazvPkorxjfPA/match-ids?queue=420&start=0&count=50&startTime=1672066800.0&endTime=1672153200.0 (api_client.py:57)
Traceback (most recent call last):
  File "C:\Users\User\PythonProject\ai-python-coach-gathering-server-1\api_client\api_client.py", line 46, in _http_request
    r.raise_for_status()
  File "C:\Users\User\AppData\Local\Packages\PythonSoftwareFoundation.Python.3.10_qbz5n2kfra8p0\LocalCache\local-packages\Python310\site-packages\requests\models.py", line 940, in raise_for_status
    raise HTTPError(http_error_msg, response=self)
requests.exceptions.HTTPError: 502 Server Error: Bad Gateway for url: https://lol.api.ggq.gg/application/v1/summoners/09h2gakf0VfGufDxZ53DgVdgyGxNhIcwvzSKZ4VRnREKcTlFlsXMQ0Li85X3BlBuzHazvPkorxjfPA/match-ids?queue=420&start=0&count=50&startTime=1672066800.0&endTime=1672153200.0
2022-12-28 20:48:06.417 [WARNING] 502 Server Error: Bad Gateway for url: https://lol.api.ggq.gg/application/v1/summoners/IcT2cevWuGlX0K_Y4GivQ-kKtwfYvnIc77ynGAno5Ah9TworyehdT-1pp6x3LQLhCTddE9hHk-xRmw (api_client.py:57)
Traceback (most recent call last):
  File "C:\Users\User\PythonProject\ai-python-coach-gathering-server-1\api_client\api_client.py", line 46, in _http_request
    r.raise_for_status()
  File "C:\Users\User\AppData\Local\Packages\PythonSoftwareFoundation.Python.3.10_qbz5n2kfra8p0\LocalCache\local-packages\Python310\site-packages\requests\models.py", line 940, in raise_for_status
    raise HTTPError(http_error_msg, response=self)
requests.exceptions.HTTPError: 502 Server Error: Bad Gateway for url: https://lol.api.ggq.gg/application/v1/summoners/IcT2cevWuGlX0K_Y4GivQ-kKtwfYvnIc77ynGAno5Ah9TworyehdT-1pp6x3LQLhCTddE9hHk-xRmw
2022-12-28 20:55:22.892 [INFO] Tier: TierGroup.P34 complete collecting (collecting_script.py:46)
2022-12-28 20:55:22.955 [INFO] User input is initialized from C:\Users\User\PythonProject\ai-python-coach-gathering-server-1\save_files\12.23\D12_user_list.txt (user_sampler.py:79)
2022-12-28 21:12:15.091 [INFO] Tier: TierGroup.D12 complete collecting (collecting_script.py:46)
2022-12-28 21:12:15.154 [INFO] User input is initialized from C:\Users\User\PythonProject\ai-python-coach-gathering-server-1\save_files\12.23\D34_user_list.txt (user_sampler.py:79)
2022-12-28 21:16:40.775 [WARNING] 502 Server Error: Bad Gateway for url: https://lol.api.ggq.gg/application/v1/summoners/QFUABa16EndlTbn1Qrlm-3Aw0uhQ2B3W4LRFv3ZcyLgHUwIMRiJSkwFL2p6dGnActwQbW3nSAkUbOw (api_client.py:57)
Traceback (most recent call last):
  File "C:\Users\User\PythonProject\ai-python-coach-gathering-server-1\api_client\api_client.py", line 46, in _http_request
    r.raise_for_status()
  File "C:\Users\User\AppData\Local\Packages\PythonSoftwareFoundation.Python.3.10_qbz5n2kfra8p0\LocalCache\local-packages\Python310\site-packages\requests\models.py", line 940, in raise_for_status
    raise HTTPError(http_error_msg, response=self)
requests.exceptions.HTTPError: 502 Server Error: Bad Gateway for url: https://lol.api.ggq.gg/application/v1/summoners/QFUABa16EndlTbn1Qrlm-3Aw0uhQ2B3W4LRFv3ZcyLgHUwIMRiJSkwFL2p6dGnActwQbW3nSAkUbOw
2022-12-28 21:24:08.111 [INFO] Tier: TierGroup.D34 complete collecting (collecting_script.py:46)
2022-12-28 21:24:08.247 [INFO] User input is initialized from C:\Users\User\PythonProject\ai-python-coach-gathering-server-1\save_files\12.23\M1_user_list.txt (user_sampler.py:79)
2022-12-28 21:35:24.089 [INFO] Tier: TierGroup.M1 complete collecting (collecting_script.py:46)
2022-12-28 21:35:24.110 [INFO] User input is initialized from C:\Users\User\PythonProject\ai-python-coach-gathering-server-1\save_files\12.23\A_user_list.txt (user_sampler.py:65)
2022-12-29 09:34:02.326 [INFO] Tier: TierGroup.A complete collecting (collecting_script.py:50)
2022-12-29 09:34:02.327 [INFO] Tier: TierGroup.A - Starting to post request to download server (collecting_script.py:57)
2022-12-29 09:36:09.215 [INFO] Tier: TierGroup.A - Complete to post request to download server (collecting_script.py:69)
2022-12-29 09:36:09.215 [INFO] current download queue: 0 (collecting_script.py:73)
2022-12-29 09:38:26.040 [INFO] 'B34' USER SAMPLING (user_sampler.py:87)
2022-12-29 09:47:14.956 [WARNING] 502 Server Error: Bad Gateway for url: https://lol.api.ggq.gg/application/v1/summoners/aly0IhN5MZNAifovVMqhVE2-fMgMou5No5cO4_nByCILx7O66zcBiqvp6VDcMCp8tABHKMP8LpTAsw (api_client.py:57)
Traceback (most recent call last):
  File "c:\Users\User\PythonProject\ai-python-coach-gathering-server-1\api_client\api_client.py", line 46, in _http_request
    r.raise_for_status()
  File "C:\Users\User\AppData\Local\Packages\PythonSoftwareFoundation.Python.3.10_qbz5n2kfra8p0\LocalCache\local-packages\Python310\site-packages\requests\models.py", line 940, in raise_for_status
    raise HTTPError(http_error_msg, response=self)
requests.exceptions.HTTPError: 502 Server Error: Bad Gateway for url: https://lol.api.ggq.gg/application/v1/summoners/aly0IhN5MZNAifovVMqhVE2-fMgMou5No5cO4_nByCILx7O66zcBiqvp6VDcMCp8tABHKMP8LpTAsw
2022-12-29 10:12:07.300 [WARNING] 500 Server Error: Internal Server Error for url: https://lol.api.ggq.gg/application/v1/summoners/2NDAQnhQHu8D2P5ZABbLn66j549qr8sXZdOPV4FSXqJ3tkV5ChTorr4RFJIhDdRuujyJSqud0JHG1g (api_client.py:57)
Traceback (most recent call last):
  File "c:\Users\User\PythonProject\ai-python-coach-gathering-server-1\api_client\api_client.py", line 46, in _http_request
    r.raise_for_status()
  File "C:\Users\User\AppData\Local\Packages\PythonSoftwareFoundation.Python.3.10_qbz5n2kfra8p0\LocalCache\local-packages\Python310\site-packages\requests\models.py", line 940, in raise_for_status
    raise HTTPError(http_error_msg, response=self)
requests.exceptions.HTTPError: 500 Server Error: Internal Server Error for url: https://lol.api.ggq.gg/application/v1/summoners/2NDAQnhQHu8D2P5ZABbLn66j549qr8sXZdOPV4FSXqJ3tkV5ChTorr4RFJIhDdRuujyJSqud0JHG1g
2022-12-29 10:25:36.038 [WARNING] 502 Server Error: Bad Gateway for url: https://lol.api.ggq.gg/application/v1/summoners/lYuy7dJi-HmJchb2mSu-jKdCkyjPjPNCl_3K0mLzveQ6wL-qXWpfdQ0uftzbsfCTwgqM5VbnPhT8AQ (api_client.py:57)
Traceback (most recent call last):
  File "c:\Users\User\PythonProject\ai-python-coach-gathering-server-1\api_client\api_client.py", line 46, in _http_request
    r.raise_for_status()
  File "C:\Users\User\AppData\Local\Packages\PythonSoftwareFoundation.Python.3.10_qbz5n2kfra8p0\LocalCache\local-packages\Python310\site-packages\requests\models.py", line 940, in raise_for_status
    raise HTTPError(http_error_msg, response=self)
requests.exceptions.HTTPError: 502 Server Error: Bad Gateway for url: https://lol.api.ggq.gg/application/v1/summoners/lYuy7dJi-HmJchb2mSu-jKdCkyjPjPNCl_3K0mLzveQ6wL-qXWpfdQ0uftzbsfCTwgqM5VbnPhT8AQ
2022-12-29 10:43:10.841 [WARNING] 500 Server Error: Internal Server Error for url: https://lol.api.ggq.gg/application/v1/summoners/gtYkv1bl0nkYSpLvbDfZGQ1IIajPJ6ZVkzcvXPLS8OJmnM0kcPH3XlvrRaU8R93BY3rx3yXRXiu_1Q (api_client.py:57)
Traceback (most recent call last):
  File "c:\Users\User\PythonProject\ai-python-coach-gathering-server-1\api_client\api_client.py", line 46, in _http_request
    r.raise_for_status()
  File "C:\Users\User\AppData\Local\Packages\PythonSoftwareFoundation.Python.3.10_qbz5n2kfra8p0\LocalCache\local-packages\Python310\site-packages\requests\models.py", line 940, in raise_for_status
    raise HTTPError(http_error_msg, response=self)
requests.exceptions.HTTPError: 500 Server Error: Internal Server Error for url: https://lol.api.ggq.gg/application/v1/summoners/gtYkv1bl0nkYSpLvbDfZGQ1IIajPJ6ZVkzcvXPLS8OJmnM0kcPH3XlvrRaU8R93BY3rx3yXRXiu_1Q
2022-12-29 10:44:04.656 [WARNING] 502 Server Error: Bad Gateway for url: https://lol.api.ggq.gg/application/v1/summoners/N2Sg-VNDZ05HjvGp27XIU6WIWEJoYkxE9Hgh9slpJeO6IWRazshin14ozcSU98drxVEjjfpooa1lbQ (api_client.py:57)
Traceback (most recent call last):
  File "c:\Users\User\PythonProject\ai-python-coach-gathering-server-1\api_client\api_client.py", line 46, in _http_request
    r.raise_for_status()
  File "C:\Users\User\AppData\Local\Packages\PythonSoftwareFoundation.Python.3.10_qbz5n2kfra8p0\LocalCache\local-packages\Python310\site-packages\requests\models.py", line 940, in raise_for_status
    raise HTTPError(http_error_msg, response=self)
requests.exceptions.HTTPError: 502 Server Error: Bad Gateway for url: https://lol.api.ggq.gg/application/v1/summoners/N2Sg-VNDZ05HjvGp27XIU6WIWEJoYkxE9Hgh9slpJeO6IWRazshin14ozcSU98drxVEjjfpooa1lbQ
2022-12-29 10:56:04.421 [WARNING] 502 Server Error: Bad Gateway for url: https://lol.api.ggq.gg/application/v1/summoners/s4sVsFP_GCKVnzm203Pe-tDLKUMohpqhLRpymkvLojwfVpHHzagbMXTRx-dAbdiat9bu6qMcG8oTZQ (api_client.py:57)
Traceback (most recent call last):
  File "c:\Users\User\PythonProject\ai-python-coach-gathering-server-1\api_client\api_client.py", line 46, in _http_request
    r.raise_for_status()
  File "C:\Users\User\AppData\Local\Packages\PythonSoftwareFoundation.Python.3.10_qbz5n2kfra8p0\LocalCache\local-packages\Python310\site-packages\requests\models.py", line 940, in raise_for_status
    raise HTTPError(http_error_msg, response=self)
requests.exceptions.HTTPError: 502 Server Error: Bad Gateway for url: https://lol.api.ggq.gg/application/v1/summoners/s4sVsFP_GCKVnzm203Pe-tDLKUMohpqhLRpymkvLojwfVpHHzagbMXTRx-dAbdiat9bu6qMcG8oTZQ
2022-12-29 11:14:08.502 [WARNING] 500 Server Error: Internal Server Error for url: https://lol.api.ggq.gg/application/v1/summoners/SNtuIZMeydbXzJKzgnltfNebTg7QavHdaNjvlXTQskP7FryZ45uRw3IcoaRiy5WkI8qfl5hVkM7oAA (api_client.py:57)
Traceback (most recent call last):
  File "c:\Users\User\PythonProject\ai-python-coach-gathering-server-1\api_client\api_client.py", line 46, in _http_request
    r.raise_for_status()
  File "C:\Users\User\AppData\Local\Packages\PythonSoftwareFoundation.Python.3.10_qbz5n2kfra8p0\LocalCache\local-packages\Python310\site-packages\requests\models.py", line 940, in raise_for_status
    raise HTTPError(http_error_msg, response=self)
requests.exceptions.HTTPError: 500 Server Error: Internal Server Error for url: https://lol.api.ggq.gg/application/v1/summoners/SNtuIZMeydbXzJKzgnltfNebTg7QavHdaNjvlXTQskP7FryZ45uRw3IcoaRiy5WkI8qfl5hVkM7oAA
2022-12-29 11:14:08.506 [WARNING] 500 Server Error: Internal Server Error for url: https://lol.api.ggq.gg/application/v1/summoners/kysmRM13-L7BA1zI3qwplZmv7z7ZTvogk_FjR4RySmN-ScoxEjKNT8uE6IYHFRbE85DDAwDpVchInA (api_client.py:57)
Traceback (most recent call last):
  File "c:\Users\User\PythonProject\ai-python-coach-gathering-server-1\api_client\api_client.py", line 46, in _http_request
    r.raise_for_status()
  File "C:\Users\User\AppData\Local\Packages\PythonSoftwareFoundation.Python.3.10_qbz5n2kfra8p0\LocalCache\local-packages\Python310\site-packages\requests\models.py", line 940, in raise_for_status
    raise HTTPError(http_error_msg, response=self)
requests.exceptions.HTTPError: 500 Server Error: Internal Server Error for url: https://lol.api.ggq.gg/application/v1/summoners/kysmRM13-L7BA1zI3qwplZmv7z7ZTvogk_FjR4RySmN-ScoxEjKNT8uE6IYHFRbE85DDAwDpVchInA
2022-12-29 11:14:08.515 [WARNING] 500 Server Error: Internal Server Error for url: https://lol.api.ggq.gg/application/v1/summoners/WQX20t4yXVYgKgg6fGdip0t810d401_glsOjvRH4VWlB2LshVE23m4ST0psULBNMRXewtA7AIYRTrw (api_client.py:57)
Traceback (most recent call last):
  File "c:\Users\User\PythonProject\ai-python-coach-gathering-server-1\api_client\api_client.py", line 46, in _http_request
    r.raise_for_status()
  File "C:\Users\User\AppData\Local\Packages\PythonSoftwareFoundation.Python.3.10_qbz5n2kfra8p0\LocalCache\local-packages\Python310\site-packages\requests\models.py", line 940, in raise_for_status
    raise HTTPError(http_error_msg, response=self)
requests.exceptions.HTTPError: 500 Server Error: Internal Server Error for url: https://lol.api.ggq.gg/application/v1/summoners/WQX20t4yXVYgKgg6fGdip0t810d401_glsOjvRH4VWlB2LshVE23m4ST0psULBNMRXewtA7AIYRTrw
2022-12-29 11:17:22.223 [WARNING] 502 Server Error: Bad Gateway for url: https://lol.api.ggq.gg/application/v1/summoners/YOLNxcdk5thEh-OwycNl7WA2EveccqtCa85uY_iKALNBQjRvWQTwgcstti0FsO6CRR0invlXVILRew (api_client.py:57)
Traceback (most recent call last):
  File "c:\Users\User\PythonProject\ai-python-coach-gathering-server-1\api_client\api_client.py", line 46, in _http_request
    r.raise_for_status()
  File "C:\Users\User\AppData\Local\Packages\PythonSoftwareFoundation.Python.3.10_qbz5n2kfra8p0\LocalCache\local-packages\Python310\site-packages\requests\models.py", line 940, in raise_for_status
    raise HTTPError(http_error_msg, response=self)
requests.exceptions.HTTPError: 502 Server Error: Bad Gateway for url: https://lol.api.ggq.gg/application/v1/summoners/YOLNxcdk5thEh-OwycNl7WA2EveccqtCa85uY_iKALNBQjRvWQTwgcstti0FsO6CRR0invlXVILRew
